Workbook
Name adawdwd: #REF!
Name adawdwd: #REF!
Name adawdwd: #REF!
Name adawdwd: #REF!
Name adawdwd: #REF!
Name adawdwd: #REF!
Name adawdwd: #REF!
Name adawdwd: #REF!
Name adawdwd: #REF!
Name Cavity: #REF!
Name Cavity: #REF!
Name Cavity: #REF!
Name Cavity: #REF!
Name Cavity: #REF!
Name Cavity: #REF!
Name Cavity: #REF!
Name Cavity: #REF!
Name Cavity: #REF!
Name Cavity: #REF!
Name Cavity: #REF!
Name Cavity: #REF!
Name Control_A2: 'GRR Plots'!$Q$105
Name CPKDrop: 'Data Selections (Hide & Lock) '!$D$6:$D$7
Name CPKValueDrop: 'Data Selections (Hide & Lock) '!$F$6:$F$7
Name Customer: #REF!
Name Customer: #REF!
Name Customer: #REF!
Name Customer: #REF!
Name Customer: #REF!
Name Customer: #REF!
Name Customer: #REF!
Name Customer: #REF!
Name Customer: #REF!
Name Customer: #REF!
Name Customer: #REF!
Name Customer: #REF!
Name Date_Req: #REF!
Name Date_Req: #REF!
Name Date_Req: #REF!
Name Date_Req: #REF!
Name Date_Req: #REF!
Name Date_Req: #REF!
Name Date_Req: #REF!
Name Date_Req: #REF!
Name Date_Req: #REF!
Name Date_Req: #REF!
Name Date_Req: #REF!
Name Date_Req: #REF!
Name Description: #REF!
Name Description: #REF!
Name Description: #REF!
Name Description: #REF!
Name Description: #REF!
Name Description: #REF!
Name Description: #REF!
Name Description: #REF!
Name Description: #REF!
Name Description: #REF!
Name Description: #REF!
Name Description: #REF!

Sheet Revision block
A1: Document # | B1: H001122
A2: Latest Revision | B2: K
A3: Revision date | B3: 45082
A4: Production Part Approval Process (PPAP)
A5: Revision | B5: Description | C5: Date | D5: Modified by
A6: A | B6: Initial release | C6: 40745 | D6: Tooling Engineering - MN
A7: B | B7: Modified instruction sheet, FAI, CPK forms Added several worksheets: Tool trial definitions, Steel measurement, Tool Steel COC, Heat Treat COC, Texture COC, Part material COC, Window study, PMP, PFD,PFMEA, Measurement instructions, Packaging instructions | C7: 41305 | D7: Tooling Engineering - MN Quality Engineering - RB
A8: C | B8: Fix compatibility issues for drop down menus in FAI/CPK sheets to be compatible with pre 2010 versions of excel | C8: 41333 | D8: Tooling Engineering - MN
A9: D | B9: Fix formula in steel measurement sheet on row 14 for after shrink calculation Fix formula error on Cp row in the "CPK" worksheet to work correctly for items tagged as a GDT feature with "YES" option Removed table from "Process Parameter" worksheet | C9: 41871 | D9: Tooling Engineering - MN
A10: E | B10: Add serial number column to the CPK worksheet Aligned the data columns to the spec columns on the CPK work sheet Modify instructions for GDT feature definition in the instruction sheet | C10: 42886 | D10: Tooling Engineering - MN
A11: F | B11: Fixed Issues with attaching files | C11: 42906 | D11: Tooling Engineering - MN
A12: G | B12: - Fixed steel measurement worksheet locked cells to be able to edit (last three columns in the header) - No longer need to enter 0.0001 for zero tolerances. (Note "For 0.00 tolerance enter 0.0001" in the instructions tab removed) - Conditional formatting added to the FAI sheet data entry cells - Change formulas in FAI sheet to enable calculations when the first column is empty - Allow formulas in the FAI sheet to work if + or - tolerance cell is blank - Add total dimension numbers calculation table on top of the FAI sheet | C12: 43493 | D12: Tooling Engineering - MN
A13: H | B13: - Correction to the total dimension numbers calculation table on top of the FAI sheet - Add conditional formatting to the CPK sheet for out of spec(Red) measurements and outliers(Orange) - Remove chart from the CPK sheet - Added Note to Instructions worksheet for GR&R, FAI and CPK data collection - Removed Grid lines from the instruction sheet - Additional instructions in FAI, CPK and GR&R section of instruction worksheet | C13: 43544 | D13: Tooling Engineering - MN
A14: J | B14: - Added "GRR Data" Tab for mass data input and GRR calculations. Format enables post-processing. - Revised GR&R: ANOVA method with rules checking, formatting, plots/graphs and explanations, enabled GR option. - Added GRR Plots Tab, toggling visual data by Dim ID. - Revised Cpk tab: ≤500 CTF, format OOS & Outlier, header required, added plots, "Submission" clarified, ±3σ ~ ±6σ tol added, low Cpk note added, Dim Type field added. - Revised FAI: Formulas accept "0" tolerance input, auto-populated GRR%. - Summary: GRR & Cpk data linked, GRR columns added, Ref tolerance data added, summary charts added. | C14: 44915 | D14: Dimensional Mgmt - LM
A15: K | B15: - Enabled "object" insert function (relaxed protections). - Cpk tab: Added Supplier Dim ID & Cavity rows. Rows 11-13 now required. Corrected Cpkl formula. - FAI tab: If Mean = 0, now displayed (was blank), if measured=0 now yellow and deviation now calculates. - GRR Data & Plots: Set conditional defaults (IF GageError>PTP Variation, set PV=0 & ndc=1) - Summary Tab: Linked Cpk by Cavity. - Rounded many calculations to 10 decimal places to mitigate near-zero rounding errors | C15: 45082 | D15: Dimensional Mgmt - LM

Sheet Table of contents
A1: Table of Contents
A2: Instructions | E2: Doc # | F2: ='Revision block'!B1 -> H001122
A3: Tool and Part Trial Definitions | E3: Rev : | F3: ='Revision block'!B2 -> K
A4: Drawing | E4: Rev date : | F4: ='Revision block'!B3 -> 45082
A5: Summary
A6: Steel Measurement
A7: Note Verifications
A8: FAI
A9: Cpk
A10: GRR Data
A11: GRR Plots
A12: Tool Steel COC
A13: Heat Treat COC
A14: Part Material COC
A15: Process Parameter
A16: Residence Time
... A22: Packaging Instructions

Sheet Instructions
A1: Table of Contents | P1: Doc # | Q1: ='Revision block'!B1 -> H001122
G2: Production Part Approval Process (PPAP) | P2: Rev : | Q2: ='Revision block'!B2 -> K
P3: Rev date : | Q3: ='Revision block'!B3 -> 45082
A9: Instructions for use
A11: General:
A12: - Do not delete any of the worksheets from the file even if they are not used and/or not required to submit
A13: - Do not copy worksheets from other files. Use the current worksheet and use paste special to copy data
A14: - For every PPAP report, use a fresh template. Do not copy from previous PPAP worksheets that are already filled out.
A15: - If you are pasting data into the spreadsheet, please "paste special" , "values". This prevents formatting from being overwritten
A16: - Parts should be marked corresponding with the sequence number on the FAI and Cpk forms
A17: - Critical dimensions are identified with a dark filled square. Process Control dimensions are denoted with a dark filled triangle on the 2D drawings
A20: Drawing Worksheet
A21: Copy and paste the 2D drawing in the Drawing worksheet, can be an embedded file
A23: Summary worksheet:
A24: Fill out all the necessary cells in the header that applies
... A43: A minimum 3 parts per cavity required for FAI measurement. This number can be increased by the request from customer
B44: Enter measurements in light blue cells for the corresponding FAI sample
B45: Unused cells may be left blank
A46: Enter the drawing number, revision number and date of the revision release in header
A47: For multiple cavities, copy the FAI worksheet after entering the header and drawing information in the original FAI worksheet form. Worksheets should be renamed to "FAI X" or "Cpk X" where X is the cavity number
A48: FAI is also required for any relevant specifications in the notes section of the drawing
B49: Item = Enter dimension number on the drawing. All drawing features and dimensions will be ballooned with a number including notes
B50: Grid square = Enter drawing zone where the ballooned dimension is located. Example 2-C3 meaning page 2 zone C3
B51: Dim Type: = Select the appropriate dim type from the drop down menu. On 2d drawings…Black square = CTF, Black triangle = Process Control Dim, (xxx.x) = Reference dim, all others are Std. dims.
B52: Nominal = Enter nominal dimension
B53: +Tol and -Tol = Enter upper and Lower tolerance on the drawing for the corresponding nominal dimension
D54: Only enter absolute values for tolerances, do not include + or -
B55: GRR = Enter the Gage repeatability and reproducibility calculation for all Critical To Function (CTF) and Process Control dimensions (PCD)
B56: Measurement Instrument = Select the type of measuring equipment used to measure the corresponding dimension from the drop down menu.
B57: Supplier action plan and comments = Here the supplier enters comments and identifies actions for correcting the out of spec dimension. Including steel safe condition or not.
C58: Supplier action plan and comments only need to be entered for dimensions that have been flagged as "Reject" or "Alert"
A59: Yes
A60: Cpk Worksheet:
A61: Perform GR&R on all CTF, CTS and PCD dimensions. Data is only valid after complete and passing GR&R for CTF, CTS and PCD dimensions
A62: Fill out the light blue highlighted cells with the collected data. Enter N/A when they are not relevant.
A63: Supplier expected to maintain tracking log, listing each Cpk study submission (log to include PN including variation suffix, date, equipment/line, etc. that describes batch of parts).
A64: Molded plastic parts for Cpk analysis are to be collected:
A65: > after 1 hour of stable operation under process parameters called out in run sheet and PMP.
A66: > One part out of every X parts molded. (X=5 unless otherwise specified)
A67: During this time, adjustments to the process are not allowed.
...

Sheet Tool and Part Trial Definitions
A1: Table of Contents | E1: Doc # | F1: ='Revision block'!B1 -> H001122
E2: Rev : | F2: ='Revision block'!B2 -> K
A3: Tool and Part Trial Definitions | E3: Rev date : | F3: ='Revision block'!B3 -> 45082
A4: 1 | B4: Part design release | C4: Preliminary 2d and 3d release for DFM iterations
A5: 2 | B5: DFM | C5: DFM iterations + start tool design concept including Jigs and fixture if necessary
A6: 3 | B6: Preliminary Tool design | C6: Provided after DFM review and approval by Tooling engineering and ME team
A7: 4 | B7: Tool design Review | C7: Reviewed by Tooling and ME team
A8: 5 | B8: Tool design approval | C8: Approval by Tooling Engineering and ME team
A9: 6 | B9: Tool kick off | C9: Final DFM, Tool design approved. Final 3d and 2d part design released for tooling
A10: 7 | B10: Tool trials | C10: All tool trials for tooling and part approval costs including press time, materials is included in original tool cost This includes 3-5 FAI parts, 30-50 Cpk parts, all measurement activities for all trials iterations until acceptable and approved All other requested sample requests at each trial will be extra
B12: T0 | C12: Tool function trial only to check for tooling function issues
C13: Run and managed by trained and skilled molding technician
C14: If no tooling function issues, collect 10 samples
C15: Check parts for tooling defects including short shot, flash, missing features, ….
C16: Preliminary fitting of the jigs and fixtures if necessary
C17: Preliminary check of the part to mating parts if available
C18: Make corrections to tooling if necessary
C19: Multiple T0 sampling may be required by supplier until all tooling issues are resolved and for preliminary process development
C20: Once all tooling issues are resolved and tooling adjustments made, proceed to T1
B22: T1 | C22: Tooling trial after all T0 and tooling issues have been corrected
C23: Run and managed by trained and skilled molding technician
C24: Process development and window study
C25: Collect 10 parts at random for GR&R data collection for measurements
C26: Collect 3-5 FAI parts after parameters are set and stable process (see instruction sheet for FAI data collection)
C27: FAI measurements to be collected after acceptable GR&R
C28: Make adjustments if necessary and proceed to T2
C29: Some T1 quantities will be required for final assembly check(this is additional cost to customer)
B31: T2 | C31: Tooling trial after all T1 and tooling and part dimensions issues have been corrected
C32: Run and managed by trained and skilled molding technician
C33: Process should be similar to T1 with minor adjustments
C34: Collect 10 parts at random for GR&R data collection for measurements
C35: Collect 3-5 FAI parts and 30-50 Cpk parts after parameters are set and stable process (see instruction sheet for FAI/Cpk/GRR data collection)
C36: FAI/Cpk measurements to be collected after acceptable GR&R
C37: Make adjustments if necessary and proceed to next trial if necessary
B39: T3, T4, Etc…. | C39: Repeat trials similar to T2 until accepted and approved
B41: TF | C41: This is after the FAI report has been approved and the supplier has been instructed to proceed to TF
C42: This is production sample. Run or managed by a production molding technician
C43: Tool must run at the approved FAI molding parameters, running fully automatic in the production molding press
C44: Robots or any other auxiliary equipment must be fully operational
C45: Process adjustments are not allowed without approval
...

Sheet Drawing
A1: Table of Contents | Q1: Doc # | R1: ='Revision block'!B1 -> H001122
B2: Attach PDF drawing here | Q2: Rev : | R2: ='Revision block'!B2 -> K
Q3: Rev date : | R3: ='Revision block'!B3 -> 45082

Sheet Summary
C1: Table of Contents | Q1: GR&R %PT Acceptance Criteria: | AD1: GRR Acceptance Limits
L2: Document Number: | O2: ='Revision block'!B1 -> H001122 | Q2: Tier 1 & Tier 1.5: | S2: 0.2 | AD2: CTS | AE2: 0.1
B3: Component PPAP Qualification Template | L3: Revision Level : | O3: ='Revision block'!B2 -> K | Q3: Tier 2: | S3: 0.3 | AD3: T1 & T1.5 | AE3: 0.2
L4: Revision Date : | O4: ='Revision block'!B3 -> 45082 | Q4: Criteria applied: | S4: 0.2 | T4: = Red | U4: ← Enter correct criteria here | AD4: T2 | AE4: 0.3
B5: 1. General Information
C6: Customer : | H6: mSOP Hyperlink: | Q6: GRR% Summary
C7: Project Name : | H7: Issue Date : | Q7: GRR Range | S7: Count | T7: Percent | U7: Spec. Ratings
C8: Asset # : | H8: Product division : | Q8: GRR > 30% | S8: =IF(S4=0.3,COUNTIF(H22:H521,">0.3"),"N/A") -> N/A | T8: =IF(OR((SUM($S$9:$S$12)=0),S8="N/A"),"",S8/SUM($S$9:$S$12)) | U8: Extended Range Tier 2 D02641 Requirements
C9: Die or Mold # : | H9: Tool Section : | Q9: 20% < GRR ≤ 30% | S9: =IF(S4=0.3,COUNTIF(H22:H521,"<="&0.3)-(S11+S12),"N/A") -> N/A | T9: =IF(OR((SUM($S$8:$S$12)=0),S9="N/A"),"",S9/SUM($S$8:$S$12))
C10: Tool Maker : | H10: Press or Injection Machine : | Q10: GRR > 20% | S10: =IF(S4=0.3,"N/A",COUNTIF(H22:H521,">0.2")) -> 0 | T10: =IF(SUM($S$8:$S$12)=0,"",S10/SUM($S$8:$S$12)) | U10: Tier 1 & Tier 1.5 H001122 PPAP Requirements
C11: Part Name : | H11: Shot Weight : | Q11: 10% < GRR ≤ 20% | S11: =COUNTIF(H22:H521,"<="&0.2)-S12 -> 0 | T11: =IF(SUM($S$8:$S$12)=0,"",S11/SUM($S$8:$S$12))
C12: Part/Product # : | H12: Product weight : | Q12: GRR ≤ 10% | S12: =COUNTIF(H22:H521,"<="&0.1) -> 0 | T12: =IF(SUM($S$8:$S$12)=0,"",S12/SUM($S$8:$S$12))
C13: Part drawing# :
C14: Rev # and date : | H14: Inspection Date : | Q14: Cpk Summary
C15: # of cavities : | H15: Prepare By : | Q15: Value | R15: X < 1.33 | S15: 1.33≤X<1.67 | T15: X ≥ 1.67
C16: Material Color : | Q16: Cpk count | R16: =COUNTIF(M22:M521,"<"&1.33) -> 0 | S16: =COUNTIF(M22:M521,"<"&1.67)-R16 -> 0 | T16: =COUNTIF(M22:M521,">="&1.67) -> 0
C17: Raw Material : | H17: Mold Shrink : | Q17: Cpk % | R17: =IF(R16="","",IF(SUM($R$16:$T$16)=0,"",R16/SUM($R$16:$T$16))) | S17: =IF(S16="","",IF(SUM($R$16:$T$16)=0,"",S16/SUM($R$16:$T$16))) | T17: =IF(T16="","",IF(SUM($R$16:$T$16)=0,"",T16/SUM($R$16:$T$16))) | V17: Approval Loop
X18: Reference Information (Tolerance Required to Attain target GRR %PT at 10%, 20% or 30% of Part Tolerance)
B20: 2.Critical Dimension And Process Dimension Capability Evaluation: | M20: Cpk by Cavity / Cell | X20: Total Tolerance for GRR% | AA20: ± Tolerance for GRR %
B21: Item # | C21: Dim# | D21: Specification (MM) | E21: USL | F21: LSL | G21: Measuring Equipment(s) | H21: GR&R %PT | I21: GR&R ndc | J21: GR&R %SD | K21: GR&R PT Observed | L21: GR&R % Repeat | M21: 1 | N21: 2 | O21: 3 | P21: 4 | Q21: 5 | R21: 6 | S21: 7 | T21: 8 | U21: Supplier comment (Supplier GRR%) | V21: Steel measurement including shrink | W21: Customer Comments | X21: 0.1 | Y21: 0.2 | Z21: 0.3 | AA21: 0.1 | AB21: 0.2 | AC21: 0.3
B22: 1 | C22: {=IF('GRR Data'!C5="","",'GRR Data'!C5)} | D22: {=IF('GRR Data'!D5="","",'GRR Data'!D5)} | E22: {=IF('GRR Data'!G5="","",'GRR Data'!G5)} | F22: {=IF('GRR Data'!H5="","",'GRR Data'!H5)} | G22: {=IF('GRR Data'!K5="","",'GRR Data'!K5)} | H22: {=TRANSPOSE('GRR Data'!DD244:WI244)} -> #VALUE! | I22: {=TRANSPOSE('GRR Data'!DD245:WI245)} -> #VALUE! | J22: {=TRANSPOSE('GRR Data'!DD246:WI246)} -> #VALUE! | K22: {=TRANSPOSE('GRR Data'!DD248:WI248)} | L22: {=TRANSPOSE('GRR Data'!DD249:WI249)} | M22: {=IF($C22="","",_xlfn.XLOOKUP($C22&M$21,#REF!&#REF!,#REF!))} | N22: {=IF($C22="","",_xlfn.XLOOKUP($C22&N$21,#REF!&#REF!,#REF!))} | O22: {=IF($C22="","",_xlfn.XLOOKUP($C22&O$21,#REF!&#REF!,#REF!))} | P22: {=IF($C22="","",_xlfn.XLOOKUP($C22&P$21,#REF!&#REF!,#REF!))} | Q22: {=IF($C22="","",_xlfn.XLOOKUP($C22&Q$21,#REF!&#REF!,#REF!))} | R22: {=IF($C22="","",_xlfn.XLOOKUP($C22&R$21,#REF!&#REF!,#REF!))} | S22: {=IF($C22="","",_xlfn.XLOOKUP($C22&S$21,#REF!&#REF!,#REF!))} | T22: {=IF($C22="","",_xlfn.XLOOKUP($C22&T$21,#REF!&#REF!,#REF!))} | X22: =IF(H22="","",(H22/$X$21)*(E22-F22)) -> #VALUE! | Y22: =IF(H22="","",(H22/$Y$21)*(E22-F22)) -> #VALUE! | Z22: =IF(H22="","",(H22/$Z$21)*(E22-F22)) -> #VALUE! | AA22: =IF(X22="","",X22/2) -> #VALUE! | AB22: =IF(Y22="","",Y22/2) -> #VALUE! | AC22: =IF(Z22="","",Z22/2) -> #VALUE!
B23: 2 | C23: {=IF('GRR Data'!C6="","",'GRR Data'!C6)} | D23: {=IF('GRR Data'!D6="","",'GRR Data'!D6)} | E23: {=IF('GRR Data'!G6="","",'GRR Data'!G6)} | F23: {=IF('GRR Data'!H6="","",'GRR Data'!H6)} | G23: {=IF('GRR Data'!K6="","",'GRR Data'!K6)} | H23: #VALUE! | I23: #VALUE! | J23: #VALUE! | M23: {=IF($C23="","",_xlfn.XLOOKUP($C23&M$21,#REF!&#REF!,#REF!))} | N23: {=IF($C23="","",_xlfn.XLOOKUP($C23&N$21,#REF!&#REF!,#REF!))} | O23: {=IF($C23="","",_xlfn.XLOOKUP($C23&O$21,#REF!&#REF!,#REF!))} | P23: {=IF($C23="","",_xlfn.XLOOKUP($C23&P$21,#REF!&#REF!,#REF!))} | Q23: {=IF($C23="","",_xlfn.XLOOKUP($C23&Q$21,#REF!&#REF!,#REF!))} | R23: {=IF($C23="","",_xlfn.XLOOKUP($C23&R$21,#REF!&#REF!,#REF!))} | S23: {=IF($C23="","",_xlfn.XLOOKUP($C23&S$21,#REF!&#REF!,#REF!))} | T23: {=IF($C23="","",_xlfn.XLOOKUP($C23&T$21,#REF!&#REF!,#REF!))} | X23: =IF(H23="","",(H23/$X$21)*(E23-F23)) -> #VALUE! | Y23: =IF(H23="","",(H23/$Y$21)*(E23-F23)) -> #VALUE! | Z23: =IF(H23="","",(H23/$Z$21)*(E23-F23)) -> #VALUE! | AA23: =IF(X23="","",X23/2) -> #VALUE! | AB23: =IF(Y23="","",Y23/2) -> #VALUE! | AC23: =IF(Z23="","",Z23/2) -> #VALUE!
B24: 3 | C24: {=IF('GRR Data'!C7="","",'GRR Data'!C7)} | D24: {=IF('GRR Data'!D7="","",'GRR Data'!D7)} | E24: {=IF('GRR Data'!G7="","",'GRR Data'!G7)} | F24: {=IF('GRR Data'!H7="","",'GRR Data'!H7)} | G24: {=IF('GRR Data'!K7="","",'GRR Data'!K7)} | H24: #VALUE! | I24: #VALUE! | J24: #VALUE! | M24: {=IF($C24="","",_xlfn.XLOOKUP($C24&M$21,#REF!&#REF!,#REF!))} | N24: {=IF($C24="","",_xlfn.XLOOKUP($C24&N$21,#REF!&#REF!,#REF!))} | O24: {=IF($C24="","",_xlfn.XLOOKUP($C24&O$21,#REF!&#REF!,#REF!))} | P24: {=IF($C24="","",_xlfn.XLOOKUP($C24&P$21,#REF!&#REF!,#REF!))} | Q24: {=IF($C24="","",_xlfn.XLOOKUP($C24&Q$21,#REF!&#REF!,#REF!))} | R24: {=IF($C24="","",_xlfn.XLOOKUP($C24&R$21,#REF!&#REF!,#REF!))} | S24: {=IF($C24="","",_xlfn.XLOOKUP($C24&S$21,#REF!&#REF!,#REF!))} | T24: {=IF($C24="","",_xlfn.XLOOKUP($C24&T$21,#REF!&#REF!,#REF!))} | X24: =IF(H24="","",(H24/$X$21)*(E24-F24)) -> #VALUE! | Y24: =IF(H24="","",(H24/$Y$21)*(E24-F24)) -> #VALUE! | Z24: =IF(H24="","",(H24/$Z$21)*(E24-F24)) -> #VALUE! | AA24: =IF(X24="","",X24/2) -> #VALUE! | AB24: =IF(Y24="","",Y24/2) -> #VALUE! | AC24: =IF(Z24="","",Z24/2) -> #VALUE!
B25: 4 | C25: {=IF('GRR Data'!C8="","",'GRR Data'!C8)} | D25: {=IF('GRR Data'!D8="","",'GRR Data'!D8)} | E25: {=IF('GRR Data'!G8="","",'GRR Data'!G8)} | F25: {=IF('GRR Data'!H8="","",'GRR Data'!H8)} | G25: {=IF('GRR Data'!K8="","",'GRR Data'!K8)} | H25: #VALUE! | I25: #VALUE! | J25: #VALUE! | M25: {=IF($C25="","",_xlfn.XLOOKUP($C25&M$21,#REF!&#REF!,#REF!))} | N25: {=IF($C25="","",_xlfn.XLOOKUP($C25&N$21,#REF!&#REF!,#REF!))} | O25: {=IF($C25="","",_xlfn.XLOOKUP($C25&O$21,#REF!&#REF!,#REF!))} | P25: {=IF($C25="","",_xlfn.XLOOKUP($C25&P$21,#REF!&#REF!,#REF!))} | Q25: {=IF($C25="","",_xlfn.XLOOKUP($C25&Q$21,#REF!&#REF!,#REF!))} | R25: {=IF($C25="","",_xlfn.XLOOKUP($C25&R$21,#REF!&#REF!,#REF!))} | S25: {=IF($C25="","",_xlfn.XLOOKUP($C25&S$21,#REF!&#REF!,#REF!))} | T25: {=IF($C25="","",_xlfn.XLOOKUP($C25&T$21,#REF!&#REF!,#REF!))} | X25: =IF(H25="","",(H25/$X$21)*(E25-F25)) -> #VALUE! | Y25: =IF(H25="","",(H25/$Y$21)*(E25-F25)) -> #VALUE! | Z25: =IF(H25="","",(H25/$Z$21)*(E25-F25)) -> #VALUE! | AA25: =IF(X25="","",X25/2) -> #VALUE! | AB25: =IF(Y25="","",Y25/2) -> #VALUE! | AC25: =IF(Z25="","",Z25/2) -> #VALUE!
B26: 5 | C26: {=IF('GRR Data'!C9="","",'GRR Data'!C9)} | D26: {=IF('GRR Data'!D9="","",'GRR Data'!D9)} | E26: {=IF('GRR Data'!G9="","",'GRR Data'!G9)} | F26: {=IF('GRR Data'!H9="","",'GRR Data'!H9)} | G26: {=IF('GRR Data'!K9="","",'GRR Data'!K9)} | H26: #VALUE! | I26: #VALUE! | J26: #VALUE! | M26: {=IF($C26="","",_xlfn.XLOOKUP($C26&M$21,#REF!&#REF!,#REF!))} | N26: {=IF($C26="","",_xlfn.XLOOKUP($C26&N$21,#REF!&#REF!,#REF!))} | O26: {=IF($C26="","",_xlfn.XLOOKUP($C26&O$21,#REF!&#REF!,#REF!))} | P26: {=IF($C26="","",_xlfn.XLOOKUP($C26&P$21,#REF!&#REF!,#REF!))} | Q26: {=IF($C26="","",_xlfn.XLOOKUP($C26&Q$21,#REF!&#REF!,#REF!))} | R26: {=IF($C26="","",_xlfn.XLOOKUP($C26&R$21,#REF!&#REF!,#REF!))} | S26: {=IF($C26="","",_xlfn.XLOOKUP($C26&S$21,#REF!&#REF!,#REF!))} | T26: {=IF($C26="","",_xlfn.XLOOKUP($C26&T$21,#REF!&#REF!,#REF!))} | X26: =IF(H26="","",(H26/$X$21)*(E26-F26)) -> #VALUE! | Y26: =IF(H26="","",(H26/$Y$21)*(E26-F26)) -> #VALUE! | Z26: =IF(H26="","",(H26/$Z$21)*(E26-F26)) -> #VALUE! | AA26: =IF(X26="","",X26/2) -> #VALUE! | AB26: =IF(Y26="","",Y26/2) -> #VALUE! | AC26: =IF(Z26="","",Z26/2) -> #VALUE!
B27: 6 | C27: {=IF('GRR Data'!C10="","",'GRR Data'!C10)} | D27: {=IF('GRR Data'!D10="","",'GRR Data'!D10)} | E27: {=IF('GRR Data'!G10="","",'GRR Data'!G10)} | F27: {=IF('GRR Data'!H10="","",'GRR Data'!H10)} | G27: {=IF('GRR Data'!K10="","",'GRR Data'!K10)} | H27: #VALUE! | I27: #VALUE! | J27: #VALUE! | M27: {=IF($C27="","",_xlfn.XLOOKUP($C27&M$21,#REF!&#REF!,#REF!))} | N27: {=IF($C27="","",_xlfn.XLOOKUP($C27&N$21,#REF!&#REF!,#REF!))} | O27: {=IF($C27="","",_xlfn.XLOOKUP($C27&O$21,#REF!&#REF!,#REF!))} | P27: {=IF($C27="","",_xlfn.XLOOKUP($C27&P$21,#REF!&#REF!,#REF!))} | Q27: {=IF($C27="","",_xlfn.XLOOKUP($C27&Q$21,#REF!&#REF!,#REF!))} | R27: {=IF($C27="","",_xlfn.XLOOKUP($C27&R$21,#REF!&#REF!,#REF!))} | S27: {=IF($C27="","",_xlfn.XLOOKUP($C27&S$21,#REF!&#REF!,#REF!))} | T27: {=IF($C27="","",_xlfn.XLOOKUP($C27&T$21,#REF!&#REF!,#REF!))} | X27: =IF(H27="","",(H27/$X$21)*(E27-F27)) -> #VALUE! | Y27: =IF(H27="","",(H27/$Y$21)*(E27-F27)) -> #VALUE! | Z27: =IF(H27="","",(H27/$Z$21)*(E27-F27)) -> #VALUE! | AA27: =IF(X27="","",X27/2) -> #VALUE! | AB27: =IF(Y27="","",Y27/2) -> #VALUE! | AC27: =IF(Z27="","",Z27/2) -> #VALUE!
B28: 7 | C28: {=IF('GRR Data'!C11="","",'GRR Data'!C11)} | D28: {=IF('GRR Data'!D11="","",'GRR Data'!D11)} | E28: {=IF('GRR Data'!G11="","",'GRR Data'!G11)} | F28: {=IF('GRR Data'!H11="","",'GRR Data'!H11)} | G28: {=IF('GRR Data'!K11="","",'GRR Data'!K11)} | H28: #VALUE! | I28: #VALUE! | J28: #VALUE! | M28: {=IF($C28="","",_xlfn.XLOOKUP($C28&M$21,#REF!&#REF!,#REF!))} | N28: {=IF($C28="","",_xlfn.XLOOKUP($C28&N$21,#REF!&#REF!,#REF!))} | O28: {=IF($C28="","",_xlfn.XLOOKUP($C28&O$21,#REF!&#REF!,#REF!))} | P28: {=IF($C28="","",_xlfn.XLOOKUP($C28&P$21,#REF!&#REF!,#REF!))} | Q28: {=IF($C28="","",_xlfn.XLOOKUP($C28&Q$21,#REF!&#REF!,#REF!))} | R28: {=IF($C28="","",_xlfn.XLOOKUP($C28&R$21,#REF!&#REF!,#REF!))} | S28: {=IF($C28="","",_xlfn.XLOOKUP($C28&S$21,#REF!&#REF!,#REF!))} | T28: {=IF($C28="","",_xlfn.XLOOKUP($C28&T$21,#REF!&#REF!,#REF!))} | X28: =IF(H28="","",(H28/$X$21)*(E28-F28)) -> #VALUE! | Y28: =IF(H28="","",(H28/$Y$21)*(E28-F28)) -> #VALUE! | Z28: =IF(H28="","",(H28/$Z$21)*(E28-F28)) -> #VALUE! | AA28: =IF(X28="","",X28/2) -> #VALUE! | AB28: =IF(Y28="","",Y28/2) -> #VALUE! | AC28: =IF(Z28="","",Z28/2) -> #VALUE!
B29: 8 | C29: {=IF('GRR Data'!C12="","",'GRR Data'!C12)} | D29: {=IF('GRR Data'!D12="","",'GRR Data'!D12)} | E29: {=IF('GRR Data'!G12="","",'GRR Data'!G12)} | F29: {=IF('GRR Data'!H12="","",'GRR Data'!H12)} | G29: {=IF('GRR Data'!K12="","",'GRR Data'!K12)} | H29: #VALUE! | I29: #VALUE! | J29: #VALUE! | M29: {=IF($C29="","",_xlfn.XLOOKUP($C29&M$21,#REF!&#REF!,#REF!))} | N29: {=IF($C29="","",_xlfn.XLOOKUP($C29&N$21,#REF!&#REF!,#REF!))} | O29: {=IF($C29="","",_xlfn.XLOOKUP($C29&O$21,#REF!&#REF!,#REF!))} | P29: {=IF($C29="","",_xlfn.XLOOKUP($C29&P$21,#REF!&#REF!,#REF!))} | Q29: {=IF($C29="","",_xlfn.XLOOKUP($C29&Q$21,#REF!&#REF!,#REF!))} | R29: {=IF($C29="","",_xlfn.XLOOKUP($C29&R$21,#REF!&#REF!,#REF!))} | S29: {=IF($C29="","",_xlfn.XLOOKUP($C29&S$21,#REF!&#REF!,#REF!))} | T29: {=IF($C29="","",_xlfn.XLOOKUP($C29&T$21,#REF!&#REF!,#REF!))} | X29: =IF(H29="","",(H29/$X$21)*(E29-F29)) -> #VALUE! | Y29: =IF(H29="","",(H29/$Y$21)*(E29-F29)) -> #VALUE! | Z29: =IF(H29="","",(H29/$Z$21)*(E29-F29)) -> #VALUE! | AA29: =IF(X29="","",X29/2) -> #VALUE! | AB29: =IF(Y29="","",Y29/2) -> #VALUE! | AC29: =IF(Z29="","",Z29/2) -> #VALUE!
B30: 9 | C30: {=IF('GRR Data'!C13="","",'GRR Data'!C13)} | D30: {=IF('GRR Data'!D13="","",'GRR Data'!D13)} | E30: {=IF('GRR Data'!G13="","",'GRR Data'!G13)} | F30: {=IF('GRR Data'!H13="","",'GRR Data'!H13)} | G30: {=IF('GRR Data'!K13="","",'GRR Data'!K13)} | H30: #VALUE! | I30: #VALUE! | J30: #VALUE! | M30: {=IF($C30="","",_xlfn.XLOOKUP($C30&M$21,#REF!&#REF!,#REF!))} | N30: {=IF($C30="","",_xlfn.XLOOKUP($C30&N$21,#REF!&#REF!,#REF!))} | O30: {=IF($C30="","",_xlfn.XLOOKUP($C30&O$21,#REF!&#REF!,#REF!))} | P30: {=IF($C30="","",_xlfn.XLOOKUP($C30&P$21,#REF!&#REF!,#REF!))} | Q30: {=IF($C30="","",_xlfn.XLOOKUP($C30&Q$21,#REF!&#REF!,#REF!))} | R30: {=IF($C30="","",_xlfn.XLOOKUP($C30&R$21,#REF!&#REF!,#REF!))} | S30: {=IF($C30="","",_xlfn.XLOOKUP($C30&S$21,#REF!&#REF!,#REF!))} | T30: {=IF($C30="","",_xlfn.XLOOKUP($C30&T$21,#REF!&#REF!,#REF!))} | X30: =IF(H30="","",(H30/$X$21)*(E30-F30)) -> #VALUE! | Y30: =IF(H30="","",(H30/$Y$21)*(E30-F30)) -> #VALUE! | Z30: =IF(H30="","",(H30/$Z$21)*(E30-F30)) -> #VALUE! | AA30: =IF(X30="","",X30/2) -> #VALUE! | AB30: =IF(Y30="","",Y30/2) -> #VALUE! | AC30: =IF(Z30="","",Z30/2) -> #VALUE!
B31: 10 | C31: {=IF('GRR Data'!C14="","",'GRR Data'!C14)} | D31: {=IF('GRR Data'!D14="","",'GRR Data'!D14)} | E31: {=IF('GRR Data'!G14="","",'GRR Data'!G14)} | F31: {=IF('GRR Data'!H14="","",'GRR Data'!H14)} | G31: {=IF('GRR Data'!K14="","",'GRR Data'!K14)} | H31: #VALUE! | I31: #VALUE! | J31: #VALUE! | M31: {=IF($C31="","",_xlfn.XLOOKUP($C31&M$21,#REF!&#REF!,#REF!))} | N31: {=IF($C31="","",_xlfn.XLOOKUP($C31&N$21,#REF!&#REF!,#REF!))} | O31: {=IF($C31="","",_xlfn.XLOOKUP($C31&O$21,#REF!&#REF!,#REF!))} | P31: {=IF($C31="","",_xlfn.XLOOKUP($C31&P$21,#REF!&#REF!,#REF!))} | Q31: {=IF($C31="","",_xlfn.XLOOKUP($C31&Q$21,#REF!&#REF!,#REF!))} | R31: {=IF($C31="","",_xlfn.XLOOKUP($C31&R$21,#REF!&#REF!,#REF!))} | S31: {=IF($C31="","",_xlfn.XLOOKUP($C31&S$21,#REF!&#REF!,#REF!))} | T31: {=IF($C31="","",_xlfn.XLOOKUP($C31&T$21,#REF!&#REF!,#REF!))} | X31: =IF(H31="","",(H31/$X$21)*(E31-F31)) -> #VALUE! | Y31: =IF(H31="","",(H31/$Y$21)*(E31-F31)) -> #VALUE! | Z31: =IF(H31="","",(H31/$Z$21)*(E31-F31)) -> #VALUE! | AA31: =IF(X31="","",X31/2) -> #VALUE! | AB31: =IF(Y31="","",Y31/2) -> #VALUE! | AC31: =IF(Z31="","",Z31/2) -> #VALUE!
B32: 11 | C32: {=IF('GRR Data'!C15="","",'GRR Data'!C15)} | D32: {=IF('GRR Data'!D15="","",'GRR Data'!D15)} | E32: {=IF('GRR Data'!G15="","",'GRR Data'!G15)} | F32: {=IF('GRR Data'!H15="","",'GRR Data'!H15)} | G32: {=IF('GRR Data'!K15="","",'GRR Data'!K15)} | H32: #VALUE! | I32: #VALUE! | J32: #VALUE! | M32: {=IF($C32="","",_xlfn.XLOOKUP($C32&M$21,#REF!&#REF!,#REF!))} | N32: {=IF($C32="","",_xlfn.XLOOKUP($C32&N$21,#REF!&#REF!,#REF!))} | O32: {=IF($C32="","",_xlfn.XLOOKUP($C32&O$21,#REF!&#REF!,#REF!))} | P32: {=IF($C32="","",_xlfn.XLOOKUP($C32&P$21,#REF!&#REF!,#REF!))} | Q32: {=IF($C32="","",_xlfn.XLOOKUP($C32&Q$21,#REF!&#REF!,#REF!))} | R32: {=IF($C32="","",_xlfn.XLOOKUP($C32&R$21,#REF!&#REF!,#REF!))} | S32: {=IF($C32="","",_xlfn.XLOOKUP($C32&S$21,#REF!&#REF!,#REF!))} | T32: {=IF($C32="","",_xlfn.XLOOKUP($C32&T$21,#REF!&#REF!,#REF!))} | X32: =IF(H32="","",(H32/$X$21)*(E32-F32)) -> #VALUE! | Y32: =IF(H32="","",(H32/$Y$21)*(E32-F32)) -> #VALUE! | Z32: =IF(H32="","",(H32/$Z$21)*(E32-F32)) -> #VALUE! | AA32: =IF(X32="","",X32/2) -> #VALUE! | AB32: =IF(Y32="","",Y32/2) -> #VALUE! | AC32: =IF(Z32="","",Z32/2) -> #VALUE!
B33: 12 | C33: {=IF('GRR Data'!C16="","",'GRR Data'!C16)} | D33: {=IF('GRR Data'!D16="","",'GRR Data'!D16)} | E33: {=IF('GRR Data'!G16="","",'GRR Data'!G16)} | F33: {=IF('GRR Data'!H16="","",'GRR Data'!H16)} | G33: {=IF('GRR Data'!K16="","",'GRR Data'!K16)} | H33: #VALUE! | I33: #VALUE! | J33: #VALUE! | M33: {=IF($C33="","",_xlfn.XLOOKUP($C33&M$21,#REF!&#REF!,#REF!))} | N33: {=IF($C33="","",_xlfn.XLOOKUP($C33&N$21,#REF!&#REF!,#REF!))} | O33: {=IF($C33="","",_xlfn.XLOOKUP($C33&O$21,#REF!&#REF!,#REF!))} | P33: {=IF($C33="","",_xlfn.XLOOKUP($C33&P$21,#REF!&#REF!,#REF!))} | Q33: {=IF($C33="","",_xlfn.XLOOKUP($C33&Q$21,#REF!&#REF!,#REF!))} | R33: {=IF($C33="","",_xlfn.XLOOKUP($C33&R$21,#REF!&#REF!,#REF!))} | S33: {=IF($C33="","",_xlfn.XLOOKUP($C33&S$21,#REF!&#REF!,#REF!))} | T33: {=IF($C33="","",_xlfn.XLOOKUP($C33&T$21,#REF!&#REF!,#REF!))} | X33: =IF(H33="","",(H33/$X$21)*(E33-F33)) -> #VALUE! | Y33: =IF(H33="","",(H33/$Y$21)*(E33-F33)) -> #VALUE! | Z33: =IF(H33="","",(H33/$Z$21)*(E33-F33)) -> #VALUE! | AA33: =IF(X33="","",X33/2) -> #VALUE! | AB33: =IF(Y33="","",Y33/2) -> #VALUE! | AC33: =IF(Z33="","",Z33/2) -> #VALUE!
B34: 13 | C34: {=IF('GRR Data'!C17="","",'GRR Data'!C17)} | D34: {=IF('GRR Data'!D17="","",'GRR Data'!D17)} | E34: {=IF('GRR Data'!G17="","",'GRR Data'!G17)} | F34: {=IF('GRR Data'!H17="","",'GRR Data'!H17)} | G34: {=IF('GRR Data'!K17="","",'GRR Data'!K17)} | H34: #VALUE! | I34: #VALUE! | J34: #VALUE! | M34: {=IF($C34="","",_xlfn.XLOOKUP($C34&M$21,#REF!&#REF!,#REF!))} | N34: {=IF($C34="","",_xlfn.XLOOKUP($C34&N$21,#REF!&#REF!,#REF!))} | O34: {=IF($C34="","",_xlfn.XLOOKUP($C34&O$21,#REF!&#REF!,#REF!))} | P34: {=IF($C34="","",_xlfn.XLOOKUP($C34&P$21,#REF!&#REF!,#REF!))} | Q34: {=IF($C34="","",_xlfn.XLOOKUP($C34&Q$21,#REF!&#REF!,#REF!))} | R34: {=IF($C34="","",_xlfn.XLOOKUP($C34&R$21,#REF!&#REF!,#REF!))} | S34: {=IF($C34="","",_xlfn.XLOOKUP($C34&S$21,#REF!&#REF!,#REF!))} | T34: {=IF($C34="","",_xlfn.XLOOKUP($C34&T$21,#REF!&#REF!,#REF!))} | X34: =IF(H34="","",(H34/$X$21)*(E34-F34)) -> #VALUE! | Y34: =IF(H34="","",(H34/$Y$21)*(E34-F34)) -> #VALUE! | Z34: =IF(H34="","",(H34/$Z$21)*(E34-F34)) -> #VALUE! | AA34: =IF(X34="","",X34/2) -> #VALUE! | AB34: =IF(Y34="","",Y34/2) -> #VALUE! | AC34: =IF(Z34="","",Z34/2) -> #VALUE!
... B521: 500 | C521: {=IF('GRR Data'!C504="","",'GRR Data'!C504)} | D521: {=IF('GRR Data'!D504="","",'GRR Data'!D504)} | E521: {=IF('GRR Data'!G504="","",'GRR Data'!G504)} | F521: {=IF('GRR Data'!H504="","",'GRR Data'!H504)} | G521: {=IF('GRR Data'!K504="","",'GRR Data'!K504)} | H521: #VALUE! | I521: #VALUE! | J521: #VALUE! | M521: {=IF($C521="","",_xlfn.XLOOKUP($C521&M$21,#REF!&#REF!,#REF!))} | N521: {=IF($C521="","",_xlfn.XLOOKUP($C521&N$21,#REF!&#REF!,#REF!))} | O521: {=IF($C521="","",_xlfn.XLOOKUP($C521&O$21,#REF!&#REF!,#REF!))} | P521: {=IF($C521="","",_xlfn.XLOOKUP($C521&P$21,#REF!&#REF!,#REF!))} | Q521: {=IF($C521="","",_xlfn.XLOOKUP($C521&Q$21,#REF!&#REF!,#REF!))} | R521: {=IF($C521="","",_xlfn.XLOOKUP($C521&R$21,#REF!&#REF!,#REF!))} | S521: {=IF($C521="","",_xlfn.XLOOKUP($C521&S$21,#REF!&#REF!,#REF!))} | T521: {=IF($C521="","",_xlfn.XLOOKUP($C521&T$21,#REF!&#REF!,#REF!))} | X521: =IF(H521="","",(H521/$X$21)*(E521-F521)) -> #VALUE! | Y521: =IF(H521="","",(H521/$Y$21)*(E521-F521)) -> #VALUE! | Z521: =IF(H521="","",(H521/$Z$21)*(E521-F521)) -> #VALUE! | AA521: =IF(X521="","",X521/2) -> #VALUE! | AB521: =IF(Y521="","",Y521/2) -> #VALUE! | AC521: =IF(Z521="","",Z521/2) -> #VALUE!
H522: =MAX(H82:H521)-MIN(H82:H521) -> #VALUE! | I522: =MAX(I82:I521)-MIN(I82:I521) -> #VALUE! | J522: =MAX(J82:J521)-MIN(J82:J521) -> #VALUE! | K522: =MAX(K82:K521)-MIN(K82:K521) -> 0 | L522: =MAX(L82:L521)-MIN(L82:L521) -> 0
B524: 3. Approval Loop
B525: a). | C525: Molder/Tool Maker
C526: Reviewed by : | G526: Title: | J526: Date:
C527: Approved by : | G527: Title: | J527: Date:
B529: b). | C529: Customer
...

Sheet Steel Measurement
A1: Table of Contents | S1: Doc # | T1: ='Revision block'!B1 -> H001122
S2: Rev : | T2: ='Revision block'!B2 -> K
B3: Steel Measurement - Critical to Fit and Function Documentation | S3: Rev date : | T3: ='Revision block'!B3 -> 45082
A5: ►This document to be reviewed by the Customer Tooling Engineering before T1 sample
A6: Part Description: | I6: Supplier: | R6: Inspected By: | AA6: New:
A7: Drawing No.: | I7: Submission No.: | R7: Inspection Date: | AA7: Revised:
A8: Revision / Date: | I8: Material Spec.: | R8: Reviewed By: | AA8: Resubmission:
A9: Mold Number:
A10: DRAWING SPECIFICATIONS | F10: Shrink % | G10: Nominal with Shrink | H10: INSPECTION RESULTS | Y10: INSPECTION ANALYSIS Toolmaker gets 25% of Drawing specification tolerance | AC10: MEAS. INST. | AD10: SUPPLIER ACTION PLAN AND COMMENTS | AE10: CUSTOMER FEEDBACK | AG10: CUSTOMER ENGINEERING DISPOSITION
H11: Actual Steel Measurement | P11: Mold Dimension (Cavity ID). - Deviation from Nominal with shrink | X11: Mean | Y11: % Tolerance | AA11: Alert / Reject | AE11: Date: | AG11: Date:
A12: Item | B12: Grid Square | C12: Nominal | D12: +Tol | E12: -Tol | H12: Cavity 1 | I12: Cavity 2 | J12: Cavity 3 | K12: Cavity 4 | L12: Cavity 5 | M12: Cavity 6 | N12: Cavity 7 | O12: Cavity 8 | P12: 1 | Q12: 2 | R12: 3 | S12: 4 | T12: 5 | U12: 6 | V12: 7 | W12: 8 | Y12: up | Z12: down | AA12: up | AB12: down
G13: =IF(C13/(1-(F13/100))=0,"",C13/(1-(F13/100))) | P13: =IF(ISERR(H13/H13)=TRUE," ",H13-$G13) | Q13: =IF(ISERR(I13/I13)=TRUE," ",I13-$G13) | R13: =IF(ISERR(J13/J13)=TRUE," ",J13-$G13) | S13: =IF(ISERR(K13/K13)=TRUE," ",K13-$G13) | T13: =IF(ISERR(L13/L13)=TRUE," ",L13-$G13) | U13: =IF(ISERR(M13/M13)=TRUE," ",M13-$G13) | V13: =IF(ISERR(N13/N13)=TRUE," ",N13-$G13) | W13: =IF(ISERR(O13/O13)=TRUE," ",O13-$G13) | X13: =IF(ISERR(H13/H13)=TRUE," ",AVERAGE(H13:O13)) | Y13: =IF(ISERR(D13/D13)=TRUE," ",IF(ISERR(H13/H13)=TRUE," ",IF(ISNUMBER($H13)=FALSE," ",IF(MAX($H13:$O13)<$G13,0,(MAX($H13:$O13)-$G13)/($D13*25%))))) | Z13: =IF(ISERR(E13/E13)=TRUE," ",IF(ISERR(H13/H13)=TRUE," ",IF(ISNUMBER(H13)=FALSE," ",IF(MIN(H13:O13)>$G13,0,($G13-MIN(H13:O13))/(E13*25%))))) | AA13: =IF(ISNUMBER($Y13)=TRUE,IF($Y13>0.651,IF($Y13>=1,"Reject","Alert")," ")," ") | AB13: =IF(ISNUMBER($Z13)=TRUE,IF($Z13>0.651,IF($Z13>=1,"Reject","Alert")," ")," ")
G14: =IF(C14/(1-(F14/100))=0,"",C14/(1-(F14/100))) | P14: =IF(ISERR(H14/H14)=TRUE," ",H14-$G14) | Q14: =IF(ISERR(I14/I14)=TRUE," ",I14-$G14) | R14: =IF(ISERR(J14/J14)=TRUE," ",J14-$G14) | S14: =IF(ISERR(K14/K14)=TRUE," ",K14-$G14) | T14: =IF(ISERR(L14/L14)=TRUE," ",L14-$G14) | U14: =IF(ISERR(M14/M14)=TRUE," ",M14-$G14) | V14: =IF(ISERR(N14/N14)=TRUE," ",N14-$G14) | W14: =IF(ISERR(O14/O14)=TRUE," ",O14-$G14) | X14: =IF(ISERR(H14/H14)=TRUE," ",AVERAGE(H14:O14)) | Y14: =IF(ISERR(D14/D14)=TRUE," ",IF(ISERR(H14/H14)=TRUE," ",IF(ISNUMBER($H14)=FALSE," ",IF(MAX($H14:$O14)<$G14,0,(MAX($H14:$O14)-$G14)/($D14*25%))))) | Z14: =IF(ISERR(E14/E14)=TRUE," ",IF(ISERR(H14/H14)=TRUE," ",IF(ISNUMBER(H14)=FALSE," ",IF(MIN(H14:O14)>$G14,0,($G14-MIN(H14:O14))/(E14*25%))))) | AA14: =IF(ISNUMBER($Y14)=TRUE,IF($Y14>0.651,IF($Y14>=1,"Reject","Alert")," ")," ") | AB14: =IF(ISNUMBER($Z14)=TRUE,IF($Z14>0.651,IF($Z14>=1,"Reject","Alert")," ")," ")
G15: =IF(C15/(1-(F15/100))=0,"",C15/(1-(F15/100))) | P15: =IF(ISERR(H15/H15)=TRUE," ",H15-$G15) | Q15: =IF(ISERR(I15/I15)=TRUE," ",I15-$G15) | R15: =IF(ISERR(J15/J15)=TRUE," ",J15-$G15) | S15: =IF(ISERR(K15/K15)=TRUE," ",K15-$G15) | T15: =IF(ISERR(L15/L15)=TRUE," ",L15-$G15) | U15: =IF(ISERR(M15/M15)=TRUE," ",M15-$G15) | V15: =IF(ISERR(N15/N15)=TRUE," ",N15-$G15) | W15: =IF(ISERR(O15/O15)=TRUE," ",O15-$G15) | X15: =IF(ISERR(H15/H15)=TRUE," ",AVERAGE(H15:O15)) | Y15: =IF(ISERR(D15/D15)=TRUE," ",IF(ISERR(H15/H15)=TRUE," ",IF(ISNUMBER($H15)=FALSE," ",IF(MAX($H15:$O15)<$G15,0,(MAX($H15:$O15)-$G15)/($D15*25%))))) | Z15: =IF(ISERR(E15/E15)=TRUE," ",IF(ISERR(H15/H15)=TRUE," ",IF(ISNUMBER(H15)=FALSE," ",IF(MIN(H15:O15)>$G15,0,($G15-MIN(H15:O15))/(E15*25%))))) | AA15: =IF(ISNUMBER($Y15)=TRUE,IF($Y15>0.651,IF($Y15>=1,"Reject","Alert")," ")," ") | AB15: =IF(ISNUMBER($Z15)=TRUE,IF($Z15>0.651,IF($Z15>=1,"Reject","Alert")," ")," ")
G16: =IF(C16/(1-(F16/100))=0,"",C16/(1-(F16/100))) | P16: =IF(ISERR(H16/H16)=TRUE," ",H16-$G16) | Q16: =IF(ISERR(I16/I16)=TRUE," ",I16-$G16) | R16: =IF(ISERR(J16/J16)=TRUE," ",J16-$G16) | S16: =IF(ISERR(K16/K16)=TRUE," ",K16-$G16) | T16: =IF(ISERR(L16/L16)=TRUE," ",L16-$G16) | U16: =IF(ISERR(M16/M16)=TRUE," ",M16-$G16) | V16: =IF(ISERR(N16/N16)=TRUE," ",N16-$G16) | W16: =IF(ISERR(O16/O16)=TRUE," ",O16-$G16) | X16: =IF(ISERR(H16/H16)=TRUE," ",AVERAGE(H16:O16)) | Y16: =IF(ISERR(D16/D16)=TRUE," ",IF(ISERR(H16/H16)=TRUE," ",IF(ISNUMBER($H16)=FALSE," ",IF(MAX($H16:$O16)<$G16,0,(MAX($H16:$O16)-$G16)/($D16*25%))))) | Z16: =IF(ISERR(E16/E16)=TRUE," ",IF(ISERR(H16/H16)=TRUE," ",IF(ISNUMBER(H16)=FALSE," ",IF(MIN(H16:O16)>$G16,0,($G16-MIN(H16:O16))/(E16*25%))))) | AA16: =IF(ISNUMBER($Y16)=TRUE,IF($Y16>0.651,IF($Y16>=1,"Reject","Alert")," ")," ") | AB16: =IF(ISNUMBER($Z16)=TRUE,IF($Z16>0.651,IF($Z16>=1,"Reject","Alert")," ")," ")
G17: =IF(C17/(1-(F17/100))=0,"",C17/(1-(F17/100))) | P17: =IF(ISERR(H17/H17)=TRUE," ",H17-$G17) | Q17: =IF(ISERR(I17/I17)=TRUE," ",I17-$G17) | R17: =IF(ISERR(J17/J17)=TRUE," ",J17-$G17) | S17: =IF(ISERR(K17/K17)=TRUE," ",K17-$G17) | T17: =IF(ISERR(L17/L17)=TRUE," ",L17-$G17) | U17: =IF(ISERR(M17/M17)=TRUE," ",M17-$G17) | V17: =IF(ISERR(N17/N17)=TRUE," ",N17-$G17) | W17: =IF(ISERR(O17/O17)=TRUE," ",O17-$G17) | X17: =IF(ISERR(H17/H17)=TRUE," ",AVERAGE(H17:O17)) | Y17: =IF(ISERR(D17/D17)=TRUE," ",IF(ISERR(H17/H17)=TRUE," ",IF(ISNUMBER($H17)=FALSE," ",IF(MAX($H17:$O17)<$G17,0,(MAX($H17:$O17)-$G17)/($D17*25%))))) | Z17: =IF(ISERR(E17/E17)=TRUE," ",IF(ISERR(H17/H17)=TRUE," ",IF(ISNUMBER(H17)=FALSE," ",IF(MIN(H17:O17)>$G17,0,($G17-MIN(H17:O17))/(E17*25%))))) | AA17: =IF(ISNUMBER($Y17)=TRUE,IF($Y17>0.651,IF($Y17>=1,"Reject","Alert")," ")," ") | AB17: =IF(ISNUMBER($Z17)=TRUE,IF($Z17>0.651,IF($Z17>=1,"Reject","Alert")," ")," ")
G18: =IF(C18/(1-(F18/100))=0,"",C18/(1-(F18/100))) | P18: =IF(ISERR(H18/H18)=TRUE," ",H18-$G18) | Q18: =IF(ISERR(I18/I18)=TRUE," ",I18-$G18) | R18: =IF(ISERR(J18/J18)=TRUE," ",J18-$G18) | S18: =IF(ISERR(K18/K18)=TRUE," ",K18-$G18) | T18: =IF(ISERR(L18/L18)=TRUE," ",L18-$G18) | U18: =IF(ISERR(M18/M18)=TRUE," ",M18-$G18) | V18: =IF(ISERR(N18/N18)=TRUE," ",N18-$G18) | W18: =IF(ISERR(O18/O18)=TRUE," ",O18-$G18) | X18: =IF(ISERR(H18/H18)=TRUE," ",AVERAGE(H18:O18)) | Y18: =IF(ISERR(D18/D18)=TRUE," ",IF(ISERR(H18/H18)=TRUE," ",IF(ISNUMBER($H18)=FALSE," ",IF(MAX($H18:$O18)<$G18,0,(MAX($H18:$O18)-$G18)/($D18*25%))))) | Z18: =IF(ISERR(E18/E18)=TRUE," ",IF(ISERR(H18/H18)=TRUE," ",IF(ISNUMBER(H18)=FALSE," ",IF(MIN(H18:O18)>$G18,0,($G18-MIN(H18:O18))/(E18*25%))))) | AA18: =IF(ISNUMBER($Y18)=TRUE,IF($Y18>0.651,IF($Y18>=1,"Reject","Alert")," ")," ") | AB18: =IF(ISNUMBER($Z18)=TRUE,IF($Z18>0.651,IF($Z18>=1,"Reject","Alert")," ")," ")
G19: =IF(C19/(1-(F19/100))=0,"",C19/(1-(F19/100))) | P19: =IF(ISERR(H19/H19)=TRUE," ",H19-$G19) | Q19: =IF(ISERR(I19/I19)=TRUE," ",I19-$G19) | R19: =IF(ISERR(J19/J19)=TRUE," ",J19-$G19) | S19: =IF(ISERR(K19/K19)=TRUE," ",K19-$G19) | T19: =IF(ISERR(L19/L19)=TRUE," ",L19-$G19) | U19: =IF(ISERR(M19/M19)=TRUE," ",M19-$G19) | V19: =IF(ISERR(N19/N19)=TRUE," ",N19-$G19) | W19: =IF(ISERR(O19/O19)=TRUE," ",O19-$G19) | X19: =IF(ISERR(H19/H19)=TRUE," ",AVERAGE(H19:O19)) | Y19: =IF(ISERR(D19/D19)=TRUE," ",IF(ISERR(H19/H19)=TRUE," ",IF(ISNUMBER($H19)=FALSE," ",IF(MAX($H19:$O19)<$G19,0,(MAX($H19:$O19)-$G19)/($D19*25%))))) | Z19: =IF(ISERR(E19/E19)=TRUE," ",IF(ISERR(H19/H19)=TRUE," ",IF(ISNUMBER(H19)=FALSE," ",IF(MIN(H19:O19)>$G19,0,($G19-MIN(H19:O19))/(E19*25%))))) | AA19: =IF(ISNUMBER($Y19)=TRUE,IF($Y19>0.651,IF($Y19>=1,"Reject","Alert")," ")," ") | AB19: =IF(ISNUMBER($Z19)=TRUE,IF($Z19>0.651,IF($Z19>=1,"Reject","Alert")," ")," ")
G20: =IF(C20/(1-(F20/100))=0,"",C20/(1-(F20/100))) | P20: =IF(ISERR(H20/H20)=TRUE," ",H20-$G20) | Q20: =IF(ISERR(I20/I20)=TRUE," ",I20-$G20) | R20: =IF(ISERR(J20/J20)=TRUE," ",J20-$G20) | S20: =IF(ISERR(K20/K20)=TRUE," ",K20-$G20) | T20: =IF(ISERR(L20/L20)=TRUE," ",L20-$G20) | U20: =IF(ISERR(M20/M20)=TRUE," ",M20-$G20) | V20: =IF(ISERR(N20/N20)=TRUE," ",N20-$G20) | W20: =IF(ISERR(O20/O20)=TRUE," ",O20-$G20) | X20: =IF(ISERR(H20/H20)=TRUE," ",AVERAGE(H20:O20)) | Y20: =IF(ISERR(D20/D20)=TRUE," ",IF(ISERR(H20/H20)=TRUE," ",IF(ISNUMBER($H20)=FALSE," ",IF(MAX($H20:$O20)<$G20,0,(MAX($H20:$O20)-$G20)/($D20*25%))))) | Z20: =IF(ISERR(E20/E20)=TRUE," ",IF(ISERR(H20/H20)=TRUE," ",IF(ISNUMBER(H20)=FALSE," ",IF(MIN(H20:O20)>$G20,0,($G20-MIN(H20:O20))/(E20*25%))))) | AA20: =IF(ISNUMBER($Y20)=TRUE,IF($Y20>0.651,IF($Y20>=1,"Reject","Alert")," ")," ") | AB20: =IF(ISNUMBER($Z20)=TRUE,IF($Z20>0.651,IF($Z20>=1,"Reject","Alert")," ")," ")
G21: =IF(C21/(1-(F21/100))=0,"",C21/(1-(F21/100))) | P21: =IF(ISERR(H21/H21)=TRUE," ",H21-$G21) | Q21: =IF(ISERR(I21/I21)=TRUE," ",I21-$G21) | R21: =IF(ISERR(J21/J21)=TRUE," ",J21-$G21) | S21: =IF(ISERR(K21/K21)=TRUE," ",K21-$G21) | T21: =IF(ISERR(L21/L21)=TRUE," ",L21-$G21) | U21: =IF(ISERR(M21/M21)=TRUE," ",M21-$G21) | V21: =IF(ISERR(N21/N21)=TRUE," ",N21-$G21) | W21: =IF(ISERR(O21/O21)=TRUE," ",O21-$G21) | X21: =IF(ISERR(H21/H21)=TRUE," ",AVERAGE(H21:O21)) | Y21: =IF(ISERR(D21/D21)=TRUE," ",IF(ISERR(H21/H21)=TRUE," ",IF(ISNUMBER($H21)=FALSE," ",IF(MAX($H21:$O21)<$G21,0,(MAX($H21:$O21)-$G21)/($D21*25%))))) | Z21: =IF(ISERR(E21/E21)=TRUE," ",IF(ISERR(H21/H21)=TRUE," ",IF(ISNUMBER(H21)=FALSE," ",IF(MIN(H21:O21)>$G21,0,($G21-MIN(H21:O21))/(E21*25%))))) | AA21: =IF(ISNUMBER($Y21)=TRUE,IF($Y21>0.651,IF($Y21>=1,"Reject","Alert")," ")," ") | AB21: =IF(ISNUMBER($Z21)=TRUE,IF($Z21>0.651,IF($Z21>=1,"Reject","Alert")," ")," ")
G22: =IF(C22/(1-(F22/100))=0,"",C22/(1-(F22/100))) | P22: =IF(ISERR(H22/H22)=TRUE," ",H22-$G22) | Q22: =IF(ISERR(I22/I22)=TRUE," ",I22-$G22) | R22: =IF(ISERR(J22/J22)=TRUE," ",J22-$G22) | S22: =IF(ISERR(K22/K22)=TRUE," ",K22-$G22) | T22: =IF(ISERR(L22/L22)=TRUE," ",L22-$G22) | U22: =IF(ISERR(M22/M22)=TRUE," ",M22-$G22) | V22: =IF(ISERR(N22/N22)=TRUE," ",N22-$G22) | W22: =IF(ISERR(O22/O22)=TRUE," ",O22-$G22) | X22: =IF(ISERR(H22/H22)=TRUE," ",AVERAGE(H22:O22)) | Y22: =IF(ISERR(D22/D22)=TRUE," ",IF(ISERR(H22/H22)=TRUE," ",IF(ISNUMBER($H22)=FALSE," ",IF(MAX($H22:$O22)<$G22,0,(MAX($H22:$O22)-$G22)/($D22*25%))))) | Z22: =IF(ISERR(E22/E22)=TRUE," ",IF(ISERR(H22/H22)=TRUE," ",IF(ISNUMBER(H22)=FALSE," ",IF(MIN(H22:O22)>$G22,0,($G22-MIN(H22:O22))/(E22*25%))))) | AA22: =IF(ISNUMBER($Y22)=TRUE,IF($Y22>0.651,IF($Y22>=1,"Reject","Alert")," ")," ") | AB22: =IF(ISNUMBER($Z22)=TRUE,IF($Z22>0.651,IF($Z22>=1,"Reject","Alert")," ")," ")
G23: =IF(C23/(1-(F23/100))=0,"",C23/(1-(F23/100))) | P23: =IF(ISERR(H23/H23)=TRUE," ",H23-$G23) | Q23: =IF(ISERR(I23/I23)=TRUE," ",I23-$G23) | R23: =IF(ISERR(J23/J23)=TRUE," ",J23-$G23) | S23: =IF(ISERR(K23/K23)=TRUE," ",K23-$G23) | T23: =IF(ISERR(L23/L23)=TRUE," ",L23-$G23) | U23: =IF(ISERR(M23/M23)=TRUE," ",M23-$G23) | V23: =IF(ISERR(N23/N23)=TRUE," ",N23-$G23) | W23: =IF(ISERR(O23/O23)=TRUE," ",O23-$G23) | X23: =IF(ISERR(H23/H23)=TRUE," ",AVERAGE(H23:O23)) | Y23: =IF(ISERR(D23/D23)=TRUE," ",IF(ISERR(H23/H23)=TRUE," ",IF(ISNUMBER($H23)=FALSE," ",IF(MAX($H23:$O23)<$G23,0,(MAX($H23:$O23)-$G23)/($D23*25%))))) | Z23: =IF(ISERR(E23/E23)=TRUE," ",IF(ISERR(H23/H23)=TRUE," ",IF(ISNUMBER(H23)=FALSE," ",IF(MIN(H23:O23)>$G23,0,($G23-MIN(H23:O23))/(E23*25%))))) | AA23: =IF(ISNUMBER($Y23)=TRUE,IF($Y23>0.651,IF($Y23>=1,"Reject","Alert")," ")," ") | AB23: =IF(ISNUMBER($Z23)=TRUE,IF($Z23>0.651,IF($Z23>=1,"Reject","Alert")," ")," ")
G24: =IF(C24/(1-(F24/100))=0,"",C24/(1-(F24/100))) | P24: =IF(ISERR(H24/H24)=TRUE," ",H24-$G24) | Q24: =IF(ISERR(I24/I24)=TRUE," ",I24-$G24) | R24: =IF(ISERR(J24/J24)=TRUE," ",J24-$G24) | S24: =IF(ISERR(K24/K24)=TRUE," ",K24-$G24) | T24: =IF(ISERR(L24/L24)=TRUE," ",L24-$G24) | U24: =IF(ISERR(M24/M24)=TRUE," ",M24-$G24) | V24: =IF(ISERR(N24/N24)=TRUE," ",N24-$G24) | W24: =IF(ISERR(O24/O24)=TRUE," ",O24-$G24) | X24: =IF(ISERR(H24/H24)=TRUE," ",AVERAGE(H24:O24)) | Y24: =IF(ISERR(D24/D24)=TRUE," ",IF(ISERR(H24/H24)=TRUE," ",IF(ISNUMBER($H24)=FALSE," ",IF(MAX($H24:$O24)<$G24,0,(MAX($H24:$O24)-$G24)/($D24*25%))))) | Z24: =IF(ISERR(E24/E24)=TRUE," ",IF(ISERR(H24/H24)=TRUE," ",IF(ISNUMBER(H24)=FALSE," ",IF(MIN(H24:O24)>$G24,0,($G24-MIN(H24:O24))/(E24*25%))))) | AA24: =IF(ISNUMBER($Y24)=TRUE,IF($Y24>0.651,IF($Y24>=1,"Reject","Alert")," ")," ") | AB24: =IF(ISNUMBER($Z24)=TRUE,IF($Z24>0.651,IF($Z24>=1,"Reject","Alert")," ")," ")
... G37: =IF(C37/(1-(F37/100))=0,"",C37/(1-(F37/100))) | P37: =IF(ISERR(H37/H37)=TRUE," ",H37-$G37) | Q37: =IF(ISERR(I37/I37)=TRUE," ",I37-$G37) | R37: =IF(ISERR(J37/J37)=TRUE," ",J37-$G37) | S37: =IF(ISERR(K37/K37)=TRUE," ",K37-$G37) | T37: =IF(ISERR(L37/L37)=TRUE," ",L37-$G37) | U37: =IF(ISERR(M37/M37)=TRUE," ",M37-$G37) | V37: =IF(ISERR(N37/N37)=TRUE," ",N37-$G37) | W37: =IF(ISERR(O37/O37)=TRUE," ",O37-$G37) | X37: =IF(ISERR(H37/H37)=TRUE," ",AVERAGE(H37:O37)) | Y37: =IF(ISERR(D37/D37)=TRUE," ",IF(ISERR(H37/H37)=TRUE," ",IF(ISNUMBER($H37)=FALSE," ",IF(MAX($H37:$O37)<$G37,0,(MAX($H37:$O37)-$G37)/($D37*25%))))) | Z37: =IF(ISERR(E37/E37)=TRUE," ",IF(ISERR(H37/H37)=TRUE," ",IF(ISNUMBER(H37)=FALSE," ",IF(MIN(H37:O37)>$G37,0,($G37-MIN(H37:O37))/(E37*25%))))) | AA37: =IF(ISNUMBER($Y37)=TRUE,IF($Y37>0.651,IF($Y37>=1,"Reject","Alert")," ")," ") | AB37: =IF(ISNUMBER($Z37)=TRUE,IF($Z37>0.651,IF($Z37>=1,"Reject","Alert")," ")," ")

Sheet Note Verifications
A1: Table of Contents
E2: Doc # | F2: ='Revision block'!B1 -> H001122
B3: Note, Raw Material & Finish Verifications | E3: Rev : | F3: ='Revision block'!B2 -> K
E4: Rev date : | F4: ='Revision block'!B3 -> 45082
A6: Note No. | B6: Note Description | C6: How Measured / Evaluated | D6: Supplier Action Plan and Comments | E6: Customer Feedback | F6: Customer Engineering Disposition
A7: 1
A8: 2
A9: 3
A10: 4
A11: 5
A12: 6
A13: 7
A14: 8
A15: 9
A16: 10
A17: 11
A18: 12
... A36: 30

Sheet FAI
C1: Table of Contents
O2: Doc # | P2: ='Revision block'!B1 -> H001122 | R2: Total Dim | T2: CTF | V2: STD | X2: Process Ctrl | Z2: Reference
B3: First Article Inspection Report | O3: Rev : | P3: ='Revision block'!B2 -> K | R3: =SUM(T3:AA3) -> 0 | T3: =COUNTIFS($D$13:$D$763,$T$2) -> 0 | V3: =COUNTIFS($D$13:$D$763,$V$2) -> 0 | X3: =COUNTIFS($D$13:$D$763,$X$2) -> 0 | Z3: =COUNTIFS($D$13:$D$763,$Z$2) -> 0
B4: Measurement values to be entered into light blue cells | O4: Rev date : | P4: ='Revision block'!B3 -> 45082 | R4: Measured | T4: =COUNTIFS($D$13:$D$763,T$2,$AL$13:$AL$763,"Y") -> 0 | U4: =IFERROR(T4/T$3,"-") -> - | V4: =COUNTIFS($D$13:$D$763,V$2,$AL$13:$AL$763,"Y") -> 0 | W4: =IFERROR(V4/V$3,"-") -> - | X4: =COUNTIFS($D$13:$D$763,X$2,$AL$13:$AL$763,"Y") -> 0 | Y4: =IFERROR(X4/X$3,"-") -> - | Z4: =COUNTIFS($D$13:$D$763,Z$2,$AL$13:$AL$763,"Y") -> 0 | AA4: =IFERROR(Z4/Z$3,"-") -> -
B5: Use "Paste Special" - "Values" if Copying data from another file or worksheet | R5: In Spec (incl Alerts) | T5: =T4-T7 -> 0 | U5: =IFERROR(T5/T$3,"-") -> - | V5: =V4-V7 -> 0 | W5: =IFERROR(V5/V$3,"-") -> - | X5: =X4-X7 -> 0 | Y5: =IFERROR(X5/X$3,"-") -> - | Z5: =Z4-Z7 -> 0 | AA5: =IFERROR(Z5/Z$3,"-") -> -
B6: Part Description: | I6: Supplier: | N6: Inspection Date: | P6: New: | R6: Alert | T6: =COUNTIFS($D$13:$D$763,T$2,$J$13:$J$763,$R6,$AK$13:$AK$763,"<>"&"""")+COUNTIFS($D$13:$D$763,T$2,$K$13:$K$763,$R6)-COUNTIFS($D$13:$D$763,T$2,$K$13:$K$763,$R6,$J$13:$J$763,$R6) -> 0 | U6: =IFERROR(T6/T$3,"-") -> - | V6: =COUNTIFS($D$13:$D$763,V$2,$J$13:$J$763,$R6,$AK$13:$AK$763,"<>"&"""")+COUNTIFS($D$13:$D$763,V$2,$K$13:$K$763,$R6)-COUNTIFS($D$13:$D$763,V$2,$K$13:$K$763,$R6,$J$13:$J$763,$R6) -> 0 | W6: =IFERROR(V6/V$3,"-") -> - | X6: =COUNTIFS($D$13:$D$763,X$2,$J$13:$J$763,$R6,$AK$13:$AK$763,"<>"&"""")+COUNTIFS($D$13:$D$763,X$2,$K$13:$K$763,$R6)-COUNTIFS($D$13:$D$763,X$2,$K$13:$K$763,$R6,$J$13:$J$763,$R6) -> 0 | Y6: =IFERROR(X6/X$3,"-") -> - | Z6: =COUNTIFS($D$13:$D$763,Z$2,$J$13:$J$763,$R6,$AK$13:$AK$763,"<>"&"""")+COUNTIFS($D$13:$D$763,Z$2,$K$13:$K$763,$R6)-COUNTIFS($D$13:$D$763,Z$2,$K$13:$K$763,$R6,$J$13:$J$763,$R6) -> 0 | AA6: =IFERROR(Z6/Z$3,"-") -> -
B7: Drawing No.: | I7: Submission No.: | N7: Cavity- / Tool No.: | P7: Revised: | R7: Reject | T7: =COUNTIFS($D$13:$D$763,T$2,$J$13:$J$763,$R7,$AK$13:$AK$763,"<>"&"""")+COUNTIFS($D$13:$D$763,T$2,$K$13:$K$763,$R7)-COUNTIFS($D$13:$D$763,T$2,$K$13:$K$763,$R7,$J$13:$J$763,$R7) -> 0 | U7: =IFERROR(T7/T$3,"-") -> - | V7: =COUNTIFS($D$13:$D$763,V$2,$J$13:$J$763,$R7,$AK$13:$AK$763,"<>"&"""")+COUNTIFS($D$13:$D$763,V$2,$K$13:$K$763,$R7)-COUNTIFS($D$13:$D$763,V$2,$K$13:$K$763,$R7,$J$13:$J$763,$R7) -> 0 | W7: =IFERROR(V7/V$3,"-") -> - | X7: =COUNTIFS($D$13:$D$763,X$2,$J$13:$J$763,$R7,$AK$13:$AK$763,"<>"&"""")+COUNTIFS($D$13:$D$763,X$2,$K$13:$K$763,$R7)-COUNTIFS($D$13:$D$763,X$2,$K$13:$K$763,$R7,$J$13:$J$763,$R7) -> 0 | Y7: =IFERROR(X7/X$3,"-") -> - | Z7: =COUNTIFS($D$13:$D$763,Z$2,$J$13:$J$763,$R7,$AK$13:$AK$763,"<>"&"""")+COUNTIFS($D$13:$D$763,Z$2,$K$13:$K$763,$R7)-COUNTIFS($D$13:$D$763,Z$2,$K$13:$K$763,$R7,$J$13:$J$763,$R7) -> 0 | AA7: =IFERROR(Z7/Z$3,"-") -> -
B8: Revision / -Date: | I8: Material Spec.: | N8: Inspector: | P8: Resubmission:
Q9: Use "Paste Special" - "Values" if Copying data from another file or worksheet
B10: DRAWING SPECIFICATIONS | H10: INSPECTION ANALYSIS | L10: GR&R | M10: MEASUREMENT INSTRUMENT | N10: SUPPLIER ACTION PLAN AND COMMENTS | O10: CUSTOMER FEEDBACK | P10: CUSTOMER ENGINEERING DISPOSITION | Q10: INSPECTION RESULTS | AL10: Type Count Y/N
H11: % Tolerance | J11: Alert / Reject | N11: Date: | O11: Date: | P11: Date: | Q11: Sample No. - Measured Value | AA11: Sample No. - Deviation from Nominal | AK11: Mean
B12: Item | C12: Grid Square | D12: Dim Type | E12: Nominal | F12: +Tol | G12: -Tol | H12: up | I12: down | J12: up | K12: down | Q12: 1 | R12: 2 | S12: 3 | T12: 4 | U12: 5 | V12: 6 | W12: 7 | X12: 8 | Y12: 9 | Z12: 10 | AA12: 1 | AB12: 2 | AC12: 3 | AD12: 4 | AE12: 5 | AF12: 6 | AG12: 7 | AH12: 8 | AI12: 9 | AJ12: 10
D13: Select Type | H13: =IF(OR(E13="",F13=""),"",IF(COUNTA(Q13:Z13)=0,"",IF(MAX($Q13:$Z13)<=$E13,0,IF(F13=0,"N/A",(MAX($Q13:$Z13)-$E13)/$F13)))) | I13: =IF(OR(E13="",G13=""),"",IF(COUNTA(Q13:Z13)=0,"",IF(MIN(Q13:Z13)>=$E13,0,IF(G13=0,"N/A",($E13-MIN(Q13:Z13))/(G13))))) | J13: =IF(H13="N/A","Reject",IF(ISNUMBER($H13)=TRUE,IF($H13>0.651,IF($H13>1.001,"Reject","Alert")," ")," ")) | K13: =IF(I13="N/A","Reject",IF(ISNUMBER($I13)=TRUE,IF($I13>0.651,IF($I13>1.001,"Reject","Alert")," ")," ")) | L13: =IF(B13="","",HLOOKUP(B13,'GRR Data'!$DD$243:$WI$244,2,FALSE)) | AA13: =IF(COUNT(Q13)=1,Q13-$E13,"") | AB13: =IF(COUNT(R13)=1,R13-$E13,"") | AC13: =IF(COUNT(S13)=1,S13-$E13,"") | AD13: =IF(COUNT(T13)=1,T13-$E13,"") | AE13: =IF(COUNT(U13)=1,U13-$E13,"") | AF13: =IF(COUNT(V13)=1,V13-$E13,"") | AG13: =IF(COUNT(W13)=1,W13-$E13,"") | AH13: =IF(COUNT(X13)=1,X13-$E13,"") | ... AJ13: =IF(COUNT(Z13)=1,Z13-$E13,"") | AK13: =IF(COUNT(Q13:Z13)=0,"",SUM(Q13:Z13)/COUNT(Q13:Z13)) | AL13: =IF(COUNT(Q13:Z13), "Y", "N") -> N
D14: Select Type | H14: =IF(OR(E14="",F14=""),"",IF(COUNTA(Q14:Z14)=0,"",IF(MAX($Q14:$Z14)<=$E14,0,IF(F14=0,"N/A",(MAX($Q14:$Z14)-$E14)/$F14)))) | I14: =IF(OR(E14="",G14=""),"",IF(COUNTA(Q14:Z14)=0,"",IF(MIN(Q14:Z14)>=$E14,0,IF(G14=0,"N/A",($E14-MIN(Q14:Z14))/(G14))))) | J14: =IF(H14="N/A","Reject",IF(ISNUMBER($H14)=TRUE,IF($H14>0.651,IF($H14>1.001,"Reject","Alert")," ")," ")) | K14: =IF(I14="N/A","Reject",IF(ISNUMBER($I14)=TRUE,IF($I14>0.651,IF($I14>1.001,"Reject","Alert")," ")," ")) | L14: =IF(B14="","",HLOOKUP(B14,'GRR Data'!$DD$243:$WI$244,2,FALSE)) | AA14: =IF(COUNT(Q14)=1,Q14-$E14,"") | AB14: =IF(COUNT(R14)=1,R14-$E14,"") | AC14: =IF(COUNT(S14)=1,S14-$E14,"") | AD14: =IF(COUNT(T14)=1,T14-$E14,"") | AE14: =IF(COUNT(U14)=1,U14-$E14,"") | AF14: =IF(COUNT(V14)=1,V14-$E14,"") | AG14: =IF(COUNT(W14)=1,W14-$E14,"") | AH14: =IF(COUNT(X14)=1,X14-$E14,"") | ... AJ14: =IF(COUNT(Z14)=1,Z14-$E14,"") | AK14: =IF(COUNT(Q14:Z14)=0,"",SUM(Q14:Z14)/COUNT(Q14:Z14)) | AL14: =IF(COUNT(Q14:Z14), "Y", "N") -> N
D15: Select Type | H15: =IF(OR(E15="",F15=""),"",IF(COUNTA(Q15:Z15)=0,"",IF(MAX($Q15:$Z15)<=$E15,0,IF(F15=0,"N/A",(MAX($Q15:$Z15)-$E15)/$F15)))) | I15: =IF(OR(E15="",G15=""),"",IF(COUNTA(Q15:Z15)=0,"",IF(MIN(Q15:Z15)>=$E15,0,IF(G15=0,"N/A",($E15-MIN(Q15:Z15))/(G15))))) | J15: =IF(H15="N/A","Reject",IF(ISNUMBER($H15)=TRUE,IF($H15>0.651,IF($H15>1.001,"Reject","Alert")," ")," ")) | K15: =IF(I15="N/A","Reject",IF(ISNUMBER($I15)=TRUE,IF($I15>0.651,IF($I15>1.001,"Reject","Alert")," ")," ")) | L15: =IF(B15="","",HLOOKUP(B15,'GRR Data'!$DD$243:$WI$244,2,FALSE)) | AA15: =IF(COUNT(Q15)=1,Q15-$E15,"") | AB15: =IF(COUNT(R15)=1,R15-$E15,"") | AC15: =IF(COUNT(S15)=1,S15-$E15,"") | AD15: =IF(COUNT(T15)=1,T15-$E15,"") | AE15: =IF(COUNT(U15)=1,U15-$E15,"") | AF15: =IF(COUNT(V15)=1,V15-$E15,"") | AG15: =IF(COUNT(W15)=1,W15-$E15,"") | AH15: =IF(COUNT(X15)=1,X15-$E15,"") | ... AJ15: =IF(COUNT(Z15)=1,Z15-$E15,"") | AK15: =IF(COUNT(Q15:Z15)=0,"",SUM(Q15:Z15)/COUNT(Q15:Z15)) | AL15: =IF(COUNT(Q15:Z15), "Y", "N") -> N
D16: Select Type | H16: =IF(OR(E16="",F16=""),"",IF(COUNTA(Q16:Z16)=0,"",IF(MAX($Q16:$Z16)<=$E16,0,IF(F16=0,"N/A",(MAX($Q16:$Z16)-$E16)/$F16)))) | I16: =IF(OR(E16="",G16=""),"",IF(COUNTA(Q16:Z16)=0,"",IF(MIN(Q16:Z16)>=$E16,0,IF(G16=0,"N/A",($E16-MIN(Q16:Z16))/(G16))))) | J16: =IF(H16="N/A","Reject",IF(ISNUMBER($H16)=TRUE,IF($H16>0.651,IF($H16>1.001,"Reject","Alert")," ")," ")) | K16: =IF(I16="N/A","Reject",IF(ISNUMBER($I16)=TRUE,IF($I16>0.651,IF($I16>1.001,"Reject","Alert")," ")," ")) | L16: =IF(B16="","",HLOOKUP(B16,'GRR Data'!$DD$243:$WI$244,2,FALSE)) | AA16: =IF(COUNT(Q16)=1,Q16-$E16,"") | AB16: =IF(COUNT(R16)=1,R16-$E16,"") | AC16: =IF(COUNT(S16)=1,S16-$E16,"") | AD16: =IF(COUNT(T16)=1,T16-$E16,"") | AE16: =IF(COUNT(U16)=1,U16-$E16,"") | AF16: =IF(COUNT(V16)=1,V16-$E16,"") | AG16: =IF(COUNT(W16)=1,W16-$E16,"") | AH16: =IF(COUNT(X16)=1,X16-$E16,"") | ... AJ16: =IF(COUNT(Z16)=1,Z16-$E16,"") | AK16: =IF(COUNT(Q16:Z16)=0,"",SUM(Q16:Z16)/COUNT(Q16:Z16)) | AL16: =IF(COUNT(Q16:Z16), "Y", "N") -> N
D17: Select Type | H17: =IF(OR(E17="",F17=""),"",IF(COUNTA(Q17:Z17)=0,"",IF(MAX($Q17:$Z17)<=$E17,0,IF(F17=0,"N/A",(MAX($Q17:$Z17)-$E17)/$F17)))) | I17: =IF(OR(E17="",G17=""),"",IF(COUNTA(Q17:Z17)=0,"",IF(MIN(Q17:Z17)>=$E17,0,IF(G17=0,"N/A",($E17-MIN(Q17:Z17))/(G17))))) | J17: =IF(H17="N/A","Reject",IF(ISNUMBER($H17)=TRUE,IF($H17>0.651,IF($H17>1.001,"Reject","Alert")," ")," ")) | K17: =IF(I17="N/A","Reject",IF(ISNUMBER($I17)=TRUE,IF($I17>0.651,IF($I17>1.001,"Reject","Alert")," ")," ")) | L17: =IF(B17="","",HLOOKUP(B17,'GRR Data'!$DD$243:$WI$244,2,FALSE)) | AA17: =IF(COUNT(Q17)=1,Q17-$E17,"") | AB17: =IF(COUNT(R17)=1,R17-$E17,"") | AC17: =IF(COUNT(S17)=1,S17-$E17,"") | AD17: =IF(COUNT(T17)=1,T17-$E17,"") | AE17: =IF(COUNT(U17)=1,U17-$E17,"") | AF17: =IF(COUNT(V17)=1,V17-$E17,"") | AG17: =IF(COUNT(W17)=1,W17-$E17,"") | AH17: =IF(COUNT(X17)=1,X17-$E17,"") | ... AJ17: =IF(COUNT(Z17)=1,Z17-$E17,"") | AK17: =IF(COUNT(Q17:Z17)=0,"",SUM(Q17:Z17)/COUNT(Q17:Z17)) | AL17: =IF(COUNT(Q17:Z17), "Y", "N") -> N
D18: Select Type | H18: =IF(OR(E18="",F18=""),"",IF(COUNTA(Q18:Z18)=0,"",IF(MAX($Q18:$Z18)<=$E18,0,IF(F18=0,"N/A",(MAX($Q18:$Z18)-$E18)/$F18)))) | I18: =IF(OR(E18="",G18=""),"",IF(COUNTA(Q18:Z18)=0,"",IF(MIN(Q18:Z18)>=$E18,0,IF(G18=0,"N/A",($E18-MIN(Q18:Z18))/(G18))))) | J18: =IF(H18="N/A","Reject",IF(ISNUMBER($H18)=TRUE,IF($H18>0.651,IF($H18>1.001,"Reject","Alert")," ")," ")) | K18: =IF(I18="N/A","Reject",IF(ISNUMBER($I18)=TRUE,IF($I18>0.651,IF($I18>1.001,"Reject","Alert")," ")," ")) | L18: =IF(B18="","",HLOOKUP(B18,'GRR Data'!$DD$243:$WI$244,2,FALSE)) | AA18: =IF(COUNT(Q18)=1,Q18-$E18,"") | AB18: =IF(COUNT(R18)=1,R18-$E18,"") | AC18: =IF(COUNT(S18)=1,S18-$E18,"") | AD18: =IF(COUNT(T18)=1,T18-$E18,"") | AE18: =IF(COUNT(U18)=1,U18-$E18,"") | AF18: =IF(COUNT(V18)=1,V18-$E18,"") | AG18: =IF(COUNT(W18)=1,W18-$E18,"") | AH18: =IF(COUNT(X18)=1,X18-$E18,"") | ... AJ18: =IF(COUNT(Z18)=1,Z18-$E18,"") | AK18: =IF(COUNT(Q18:Z18)=0,"",SUM(Q18:Z18)/COUNT(Q18:Z18)) | AL18: =IF(COUNT(Q18:Z18), "Y", "N") -> N
D19: Select Type | H19: =IF(OR(E19="",F19=""),"",IF(COUNTA(Q19:Z19)=0,"",IF(MAX($Q19:$Z19)<=$E19,0,IF(F19=0,"N/A",(MAX($Q19:$Z19)-$E19)/$F19)))) | I19: =IF(OR(E19="",G19=""),"",IF(COUNTA(Q19:Z19)=0,"",IF(MIN(Q19:Z19)>=$E19,0,IF(G19=0,"N/A",($E19-MIN(Q19:Z19))/(G19))))) | J19: =IF(H19="N/A","Reject",IF(ISNUMBER($H19)=TRUE,IF($H19>0.651,IF($H19>1.001,"Reject","Alert")," ")," ")) | K19: =IF(I19="N/A","Reject",IF(ISNUMBER($I19)=TRUE,IF($I19>0.651,IF($I19>1.001,"Reject","Alert")," ")," ")) | L19: =IF(B19="","",HLOOKUP(B19,'GRR Data'!$DD$243:$WI$244,2,FALSE)) | AA19: =IF(COUNT(Q19)=1,Q19-$E19,"") | AB19: =IF(COUNT(R19)=1,R19-$E19,"") | AC19: =IF(COUNT(S19)=1,S19-$E19,"") | AD19: =IF(COUNT(T19)=1,T19-$E19,"") | AE19: =IF(COUNT(U19)=1,U19-$E19,"") | AF19: =IF(COUNT(V19)=1,V19-$E19,"") | AG19: =IF(COUNT(W19)=1,W19-$E19,"") | AH19: =IF(COUNT(X19)=1,X19-$E19,"") | ... AJ19: =IF(COUNT(Z19)=1,Z19-$E19,"") | AK19: =IF(COUNT(Q19:Z19)=0,"",SUM(Q19:Z19)/COUNT(Q19:Z19)) | AL19: =IF(COUNT(Q19:Z19), "Y", "N") -> N
D20: Select Type | H20: =IF(OR(E20="",F20=""),"",IF(COUNTA(Q20:Z20)=0,"",IF(MAX($Q20:$Z20)<=$E20,0,IF(F20=0,"N/A",(MAX($Q20:$Z20)-$E20)/$F20)))) | I20: =IF(OR(E20="",G20=""),"",IF(COUNTA(Q20:Z20)=0,"",IF(MIN(Q20:Z20)>=$E20,0,IF(G20=0,"N/A",($E20-MIN(Q20:Z20))/(G20))))) | J20: =IF(H20="N/A","Reject",IF(ISNUMBER($H20)=TRUE,IF($H20>0.651,IF($H20>1.001,"Reject","Alert")," ")," ")) | K20: =IF(I20="N/A","Reject",IF(ISNUMBER($I20)=TRUE,IF($I20>0.651,IF($I20>1.001,"Reject","Alert")," ")," ")) | L20: =IF(B20="","",HLOOKUP(B20,'GRR Data'!$DD$243:$WI$244,2,FALSE)) | AA20: =IF(COUNT(Q20)=1,Q20-$E20,"") | AB20: =IF(COUNT(R20)=1,R20-$E20,"") | AC20: =IF(COUNT(S20)=1,S20-$E20,"") | AD20: =IF(COUNT(T20)=1,T20-$E20,"") | AE20: =IF(COUNT(U20)=1,U20-$E20,"") | AF20: =IF(COUNT(V20)=1,V20-$E20,"") | AG20: =IF(COUNT(W20)=1,W20-$E20,"") | AH20: =IF(COUNT(X20)=1,X20-$E20,"") | ... AJ20: =IF(COUNT(Z20)=1,Z20-$E20,"") | AK20: =IF(COUNT(Q20:Z20)=0,"",SUM(Q20:Z20)/COUNT(Q20:Z20)) | AL20: =IF(COUNT(Q20:Z20), "Y", "N") -> N
D21: Select Type | H21: =IF(OR(E21="",F21=""),"",IF(COUNTA(Q21:Z21)=0,"",IF(MAX($Q21:$Z21)<=$E21,0,IF(F21=0,"N/A",(MAX($Q21:$Z21)-$E21)/$F21)))) | I21: =IF(OR(E21="",G21=""),"",IF(COUNTA(Q21:Z21)=0,"",IF(MIN(Q21:Z21)>=$E21,0,IF(G21=0,"N/A",($E21-MIN(Q21:Z21))/(G21))))) | J21: =IF(H21="N/A","Reject",IF(ISNUMBER($H21)=TRUE,IF($H21>0.651,IF($H21>1.001,"Reject","Alert")," ")," ")) | K21: =IF(I21="N/A","Reject",IF(ISNUMBER($I21)=TRUE,IF($I21>0.651,IF($I21>1.001,"Reject","Alert")," ")," ")) | L21: =IF(B21="","",HLOOKUP(B21,'GRR Data'!$DD$243:$WI$244,2,FALSE)) | AA21: =IF(COUNT(Q21)=1,Q21-$E21,"") | AB21: =IF(COUNT(R21)=1,R21-$E21,"") | AC21: =IF(COUNT(S21)=1,S21-$E21,"") | AD21: =IF(COUNT(T21)=1,T21-$E21,"") | AE21: =IF(COUNT(U21)=1,U21-$E21,"") | AF21: =IF(COUNT(V21)=1,V21-$E21,"") | AG21: =IF(COUNT(W21)=1,W21-$E21,"") | AH21: =IF(COUNT(X21)=1,X21-$E21,"") | ... AJ21: =IF(COUNT(Z21)=1,Z21-$E21,"") | AK21: =IF(COUNT(Q21:Z21)=0,"",SUM(Q21:Z21)/COUNT(Q21:Z21)) | AL21: =IF(COUNT(Q21:Z21), "Y", "N") -> N
